


          
这是一个完整的 `co` 函数实现，用于自动执行 Generator 函数并处理异步操作。让我详细解释每个部分：

## 函数签名与返回值
```javascript
function co(generatorFunction) {
    return new Promise((resolve, reject) => {
        // ...
    })
}
```
- **参数**：`generatorFunction` - 一个生成器函数
- **返回值**：Promise 对象，用于处理最终结果或错误

## 核心执行逻辑

### 1. 创建迭代器
```javascript
const g = generatorFunction() // 得到一个可迭代对象/迭代器
```
调用生成器函数，获得迭代器对象，用于控制 Generator 的执行流程。

### 2. 递归执行函数 `next`
```javascript
function next(value) {
    try {
        const {value: result, done} = g.next(value)
        // ...
    } catch (e) {
        reject(e)
    }
}
```
- **参数**：`value` - 传递给 Generator 的值（第一次调用为 undefined）
- **作用**：推进 Generator 执行到下一个 `yield` 点
- **异常处理**：捕获同步错误并拒绝 Promise

### 3. 完成状态处理
```javascript
if (done) {
    resolve(result)
}
```
当 Generator 执行完毕（`done: true`）时，用最终结果解决 Promise。

### 4. 异步值处理
```javascript
else {
    Promise.resolve(result)
    .then(next)
    .catch((err) => {
        // 错误处理逻辑
    })
}
```
**关键设计**：
- `Promise.resolve(result)` 统一处理同步值和异步 Promise
- `.then(next)` 将异步结果传递给下一次迭代
- 实现了异步等待机制

### 5. 错误传播机制
```javascript
.catch((err) => {
    try {
        const {value: result, done} = g.throw(err)
        if (done) {
            resolve(result)
        } else {
            Promise.resolve(result).then(next).catch(reject)
        }
    } catch (e) {
        reject(e)
    }
})
```
**核心机制**：
- `g.throw(err)` 将错误"注入"到 Generator 当前 `yield` 位置
- Generator 可通过 `try-catch` 捕获并处理错误
- 如果 Generator 内部处理了错误，继续执行；否则拒绝 Promise

## 执行流程示例

```javascript
function* example() {
    try {
        const result1 = yield fetch('/api/data1'); // 异步操作
        const result2 = yield fetch('/api/data2'); // 继续异步操作
        return result1 + result2;
    } catch (error) {
        console.log('处理错误:', error);
        return 'fallback';
    }
}

co(example); // 自动执行整个异步流程
```

## 技术亮点

1. **异步自动化**：无需手动调用 `next()`，自动处理异步流程
2. **错误传播**：完美模拟 `async/await` 的错误处理机制
3. **值统一处理**：`Promise.resolve()` 统一处理同步值和 Promise
4. **递归设计**：通过递归实现连续的异步操作执行
5. **状态管理**：正确处理 Generator 的完成状态

这就是 `async/await` 语法糖的底层实现原理！`co` 函数是 `async/await` 的前身，展示了如何用 Generator + Promise 实现优雅的异步流程控制。
        






          
通过这段代码可以清楚地判断 Generator 函数内部是否捕获了错误，关键在于 `g.throw(err)` 的执行结果：

## 判断机制解析

### 1. `g.throw(err)` 的两种结果

```javascript
try {
    const {value: result, done} = g.throw(err)
    // 如果执行到这里，说明 Generator 内部捕获了错误
} catch (e) {
    // 如果执行到这里，说明 Generator 内部没有捕获错误
    reject(e)
}
```

### 2. Generator 内部有错误处理的情况

当 Generator 内部有 `try-catch` 时：
```javascript
function* gen() {
    try {
        const result = yield Promise.reject('错误');
    } catch (e) {
        console.log('内部捕获:', e); // 会执行这里
        return 'fallback'; // 或继续执行其他逻辑
    }
}
```

**执行流程**：
- `g.throw(err)` 将错误注入到 `yield` 位置
- Generator 内部的 `catch` 捕获错误
- `g.throw(err)` **正常返回** `{value: 'fallback', done: true}`
- 代码继续执行 `if (done)` 分支，最终 `resolve(result)`

### 3. Generator 内部没有错误处理的情况

当 Generator 内部没有 `try-catch` 时：
```javascript
function* gen() {
    const result = yield Promise.reject('错误'); // 没有 try-catch
    return result;
}
```

**执行流程**：
- `g.throw(err)` 将错误注入到 `yield` 位置
- Generator 内部没有捕获，错误继续向上抛出
- `g.throw(err)` **抛出异常**
- 外层的 `catch (e)` 捕获异常，执行 `reject(e)`

## 核心判断逻辑

```javascript
try {
    const {value: result, done} = g.throw(err)
    // 能执行到这里 = Generator 内部处理了错误
    if (done) {
        resolve(result) // Generator 完成，返回处理后的结果
    } else {
        Promise.resolve(result).then(next).catch(reject) // Generator 继续执行
    }
} catch (e) {
    // 执行到这里 = Generator 内部没有处理错误
    reject(e) // 直接拒绝整个 co 函数的 Promise
}
```

## 实际应用场景

在做后台管理系统时，这种机制特别有用：

```javascript
function* fetchUserData() {
    try {
        const user = yield api.getUser();
        const permissions = yield api.getPermissions(user.id);
        return { user, permissions };
    } catch (error) {
        // 内部处理：显示友好提示，返回默认数据
        showNotification('获取用户信息失败，使用默认配置');
        return { user: null, permissions: [] };
    }
}
```

这样，即使 API 调用失败，应用也能优雅降级，而不是直接崩溃。

**总结**：通过 `try-catch` 包裹 `g.throw(err)`，可以精确判断 Generator 是否有内部错误处理能力，从而决定是继续执行还是终止整个异步流程。
        